<?xml version="1.0" ?>
<robot name="urdf_assembly" xmlns:xacro="http://www.ros.org/wiki/xacro">

<xacro:include filename="$(find urdf_assembly_description)/urdf/materials.xacro" />
<xacro:include filename="$(find urdf_assembly_description)/urdf/urdf_assembly.trans" />
<xacro:include filename="$(find urdf_assembly_description)/urdf/urdf_assembly.gazebo" />
<link name="base_link">
  <inertial>
    <origin xyz="-0.004121849944899078 -0.034009652002123754 0.037270068439085986" rpy="0 0 0"/>
    <mass value="2.200366644976027"/>
    <inertia ixx="0.02691" iyy="0.015633" izz="0.040737" ixy="-0.000363" iyz="0.001133" ixz="-0.000114"/>
  </inertial>
  <visual>
    <origin xyz="0 0 0" rpy="0 0 0"/>
    <geometry>
      <mesh filename="package://urdf_assembly_description/meshes/base_link.stl" scale="0.001 0.001 0.001"/>
    </geometry>
    <material name="silver"/>
  </visual>
  <collision>
    <origin xyz="0 0 0" rpy="0 0 0"/>
    <geometry>
      <mesh filename="package://urdf_assembly_description/meshes/base_link.stl" scale="0.001 0.001 0.001"/>
    </geometry>
  </collision>
</link>

<link name="link_1_1">
  <inertial>
    <origin xyz="-0.0006648527983475366 -0.034739286319087175 0.024001498636141927" rpy="0 0 0"/>
    <mass value="2.030739431813925"/>
    <inertia ixx="0.014477" iyy="0.006803" izz="0.0131" ixy="-0.000145" iyz="0.000726" ixz="1.6e-05"/>
  </inertial>
  <visual>
    <origin xyz="0.002859 0.002632 -0.117341" rpy="0 0 0"/>
    <geometry>
      <mesh filename="package://urdf_assembly_description/meshes/link_1_1.stl" scale="0.001 0.001 0.001"/>
    </geometry>
    <material name="silver"/>
  </visual>
  <collision>
    <origin xyz="0.002859 0.002632 -0.117341" rpy="0 0 0"/>
    <geometry>
      <mesh filename="package://urdf_assembly_description/meshes/link_1_1.stl" scale="0.001 0.001 0.001"/>
    </geometry>
  </collision>
</link>

<link name="link_2_1">
  <inertial>
    <origin xyz="0.04511187920706202 -2.6052271949645028e-05 0.13687546860146899" rpy="0 0 0"/>
    <mass value="1.6626610036452254"/>
    <inertia ixx="0.024251" iyy="0.026584" izz="0.005086" ixy="0.0" iyz="7e-06" ixz="-2.6e-05"/>
  </inertial>
  <visual>
    <origin xyz="0.048859 0.002632 -0.199341" rpy="0 0 0"/>
    <geometry>
      <mesh filename="package://urdf_assembly_description/meshes/link_2_1.stl" scale="0.001 0.001 0.001"/>
    </geometry>
    <material name="silver"/>
  </visual>
  <collision>
    <origin xyz="0.048859 0.002632 -0.199341" rpy="0 0 0"/>
    <geometry>
      <mesh filename="package://urdf_assembly_description/meshes/link_2_1.stl" scale="0.001 0.001 0.001"/>
    </geometry>
  </collision>
</link>

<link name="link_3_1">
  <inertial>
    <origin xyz="0.04583877141246071 -0.016283006892585307 0.07497937866412202" rpy="0 0 0"/>
    <mass value="9.121346283290384"/>
    <inertia ixx="0.063998" iyy="0.062586" izz="0.038355" ixy="2.5e-05" iyz="0.007821" ixz="-0.000107"/>
  </inertial>
  <visual>
    <origin xyz="0.048859 0.002793 -0.498507" rpy="0 0 0"/>
    <geometry>
      <mesh filename="package://urdf_assembly_description/meshes/link_3_1.stl" scale="0.001 0.001 0.001"/>
    </geometry>
    <material name="silver"/>
  </visual>
  <collision>
    <origin xyz="0.048859 0.002793 -0.498507" rpy="0 0 0"/>
    <geometry>
      <mesh filename="package://urdf_assembly_description/meshes/link_3_1.stl" scale="0.001 0.001 0.001"/>
    </geometry>
  </collision>
</link>

<link name="link_4_1">
  <inertial>
    <origin xyz="1.8555223852637776e-07 0.29134771342807086 5.953620085041855e-06" rpy="0 0 0"/>
    <mass value="10.054299804651304"/>
    <inertia ixx="0.155266" iyy="0.047315" izz="0.195922" ixy="-1e-06" iyz="-1e-06" ixz="0.0"/>
  </inertial>
  <visual>
    <origin xyz="0.002859 0.112793 -0.596394" rpy="0 0 0"/>
    <geometry>
      <mesh filename="package://urdf_assembly_description/meshes/link_4_1.stl" scale="0.001 0.001 0.001"/>
    </geometry>
    <material name="silver"/>
  </visual>
  <collision>
    <origin xyz="0.002859 0.112793 -0.596394" rpy="0 0 0"/>
    <geometry>
      <mesh filename="package://urdf_assembly_description/meshes/link_4_1.stl" scale="0.001 0.001 0.001"/>
    </geometry>
  </collision>
</link>

<link name="link_5_1">
  <inertial>
    <origin xyz="0.03000018741301736 0.000972331618348532 3.826902683634614e-08" rpy="0 0 0"/>
    <mass value="0.9450165378323743"/>
    <inertia ixx="0.001097" iyy="0.001165" izz="0.001181" ixy="-0.0" iyz="-0.0" ixz="0.0"/>
  </inertial>
  <visual>
    <origin xyz="0.032859 -0.290546 -0.596394" rpy="0 0 0"/>
    <geometry>
      <mesh filename="package://urdf_assembly_description/meshes/link_5_1.stl" scale="0.001 0.001 0.001"/>
    </geometry>
    <material name="silver"/>
  </visual>
  <collision>
    <origin xyz="0.032859 -0.290546 -0.596394" rpy="0 0 0"/>
    <geometry>
      <mesh filename="package://urdf_assembly_description/meshes/link_5_1.stl" scale="0.001 0.001 0.001"/>
    </geometry>
  </collision>
</link>

<link name="link_6_1">
  <inertial>
    <origin xyz="-0.0008044458700048728 0.058470285192862737 -0.0016142701264050263" rpy="0 0 0"/>
    <mass value="2.2763198278689676"/>
    <inertia ixx="0.002157" iyy="0.001838" izz="0.002304" ixy="2.1e-05" iyz="4.2e-05" ixz="6.9e-05"/>
  </inertial>
  <visual>
    <origin xyz="0.002859 -0.328546 -0.596394" rpy="0 0 0"/>
    <geometry>
      <mesh filename="package://urdf_assembly_description/meshes/link_6_1.stl" scale="0.001 0.001 0.001"/>
    </geometry>
    <material name="silver"/>
  </visual>
  <collision>
    <origin xyz="0.002859 -0.328546 -0.596394" rpy="0 0 0"/>
    <geometry>
      <mesh filename="package://urdf_assembly_description/meshes/link_6_1.stl" scale="0.001 0.001 0.001"/>
    </geometry>
  </collision>
</link>

<link name="link_7_1">
  <inertial>
    <origin xyz="0.0052891593258863195 0.05604372114344347 -0.03454522222823053" rpy="0 0 0"/>
    <mass value="0.8308399781572773"/>
    <inertia ixx="0.001677" iyy="0.000955" izz="0.000833" ixy="5e-05" iyz="3e-06" ixz="1e-06"/>
  </inertial>
  <visual>
    <origin xyz="-0.01211 -0.398546 -0.630669" rpy="0 0 0"/>
    <geometry>
      <mesh filename="package://urdf_assembly_description/meshes/link_7_1.stl" scale="0.001 0.001 0.001"/>
    </geometry>
    <material name="silver"/>
  </visual>
  <collision>
    <origin xyz="-0.01211 -0.398546 -0.630669" rpy="0 0 0"/>
    <geometry>
      <mesh filename="package://urdf_assembly_description/meshes/link_7_1.stl" scale="0.001 0.001 0.001"/>
    </geometry>
  </collision>
</link>

<link name="link_6__1__1">
  <inertial>
    <origin xyz="-0.005492085420059134 0.05617103138911078 -0.03817503247390752" rpy="0 0 0"/>
    <mass value="0.8293395046016687"/>
    <inertia ixx="0.001672" iyy="0.000956" izz="0.000827" ixy="-4.8e-05" iyz="-0.0" ixz="-1e-06"/>
  </inertial>
  <visual>
    <origin xyz="0.01809 -0.398546 -0.634569" rpy="0 0 0"/>
    <geometry>
      <mesh filename="package://urdf_assembly_description/meshes/link_6__1__1.stl" scale="0.001 0.001 0.001"/>
    </geometry>
    <material name="silver"/>
  </visual>
  <collision>
    <origin xyz="0.01809 -0.398546 -0.634569" rpy="0 0 0"/>
    <geometry>
      <mesh filename="package://urdf_assembly_description/meshes/link_6__1__1.stl" scale="0.001 0.001 0.001"/>
    </geometry>
  </collision>
</link>

<joint name="joint_1" type="continuous">
  <origin xyz="-0.002859 -0.002632 0.117341" rpy="0 0 0"/>
  <parent link="base_link"/>
  <child link="link_1_1"/>
  <axis xyz="-0.0 -0.0 1.0"/>
</joint>

<joint name="joint_2" type="revolute">
  <origin xyz="-0.046 0.0 0.082" rpy="0 0 0"/>
  <parent link="link_1_1"/>
  <child link="link_2_1"/>
  <axis xyz="-1.0 -0.0 -0.0"/>
  <limit upper="1.570796" lower="-0.872665" effort="100" velocity="100"/>
</joint>

<joint name="joint_3" type="revolute">
  <origin xyz="0.0 -0.000161 0.299166" rpy="0 0 0"/>
  <parent link="link_2_1"/>
  <child link="link_3_1"/>
  <axis xyz="1.0 0.0 0.0"/>
  <limit upper="1.570796" lower="-1.570796" effort="100" velocity="100"/>
</joint>

<joint name="joint_4" type="continuous">
  <origin xyz="0.046 -0.11 0.097887" rpy="0 0 0"/>
  <parent link="link_3_1"/>
  <child link="link_4_1"/>
  <axis xyz="-0.0 1.0 -0.0"/>
</joint>

<joint name="joint_5" type="revolute">
  <origin xyz="-0.03 0.403339 0.0" rpy="0 0 0"/>
  <parent link="link_4_1"/>
  <child link="link_5_1"/>
  <axis xyz="1.0 0.0 0.0"/>
  <limit upper="2.443461" lower="-2.181662" effort="100" velocity="100"/>
</joint>

<joint name="joint_6" type="continuous">
  <origin xyz="0.03 0.038 0.0" rpy="0 0 0"/>
  <parent link="link_5_1"/>
  <child link="link_6_1"/>
  <axis xyz="0.0 -1.0 -0.0"/>
</joint>

<joint name="joint_7" type="revolute">
  <origin xyz="0.014969 0.07 0.034275" rpy="0 0 0"/>
  <parent link="link_6_1"/>
  <child link="link_7_1"/>
  <axis xyz="-0.0 -0.0 1.0"/>
  <limit upper="0.0" lower="-1.570796" effort="100" velocity="100"/>
</joint>

<joint name="joint_8" type="revolute">
  <origin xyz="-0.015231 0.07 0.038175" rpy="0 0 0"/>
  <parent link="link_6_1"/>
  <child link="link_6__1__1"/>
  <axis xyz="-0.0 -0.0 1.0"/>
  <limit upper="1.570796" lower="0.0" effort="100" velocity="100"/>
</joint>

</robot>
